<?xml version="1.0" encoding="utf-8"?>
<robot name="k3lso" xmlns:xacro="http://www.ros.org/wiki/xacro">
  <material name="black">
    <color rgba="0.6 0.6 0.6 1"/>
  </material>
  <material name="white">
    <color rgba="(255, 255, 255, 1"/>
  </material>
  <!-- Params -->
  <!-- Macros -->
  <!-- Robot Body -->
  <link name="body">
    <inertial>
      <origin xyz="0.0 0.0 0.0"/>	
      <origin rpy="0 0 0" xyz="0.02003748539570111 -0.0071304890141553725 -0.4"/>
      <mass value="7"/>
      <inertia ixx="2.716E+07" ixy="-7.231E+04" ixz="-1.353E+06" iyy="2.858E+08" iyz="8.786E+04" izz="2.898E+08"/>
    </inertial>
    <visual>
      <origin rpy="0 0 0" xyz="0 0 0"/>
      <geometry>
        <mesh filename="stl/base_link.stl" scale="0.001 0.001 0.001"/>
      </geometry>
      <material name="black"/>
    </visual>
    <collision>
      <origin rpy="0 0 0" xyz="0 0 0"/>
      <geometry>
        <mesh filename="stl/base_link.stl" scale="0.001 0.001 0.001"/>
      </geometry>
    </collision>
  </link>
    <!--!!!!!!!!!!!! Front Right Leg !!!!!!!!!!!!!!!!!!!!!!!!!!!!!!!!!!!!-->
    <joint name="torso_to_abduct_fr_j" type="continuous">
        <axis xyz="1.0 0.0 0.0"/>
        <origin rpy="0 0 0" xyz="0.194567 -0.061294 0.003592"/>
        <parent link="body"/>
        <child link="abduct_fr"/>
    </joint>
    <link name="abduct_fr">
    <inertial>
      <origin rpy="0 0 0" xyz="0.05316643515331204 -0.0005506334390520187 0.0005858398004497394"/>
      <mass value="1.114"/>
      <inertia ixx="0.002477" ixy="1.3e-05" ixz="3.2e-05" iyy="0.003947" iyz="-1.1e-05" izz="0.002928"/>
    </inertial>
    <visual>
      <origin rpy="0 0 0" xyz="-0.194567 0.061294 -0.003592"/>
      <geometry>
        <mesh filename="stl/lh_hip_1.stl" scale="0.001 0.001 0.001"/>
      </geometry>
      <material name="black"/>
    </visual>
    <collision>
      <origin rpy="0 0 0" xyz="-0.194567 0.061294 -0.003592"/>
      <geometry>
        <mesh filename="stl/lh_hip_1.stl" scale="0.001 0.001 0.001"/>
      </geometry>
    </collision>
    </link>

    <joint name="abduct_fr_to_thigh_fr_j" type="continuous">
        <axis xyz="0.0 -1.0 0.0"/>
        <origin rpy="0 0 0" xyz="0.05792 -0.03115 0.0"/>
        <parent link="abduct_fr"/>
        <child link="thigh_fr"/>
    </joint>
    <link name="thigh_fr">
    <inertial>
      <origin rpy="0 0 0" xyz="-0.00047095982667560987 -0.058137385583802687 -0.029251580623966024"/>
      <mass value="1.575"/>
      <inertia ixx="0.025689" ixy="7.8e-05" ixz="3.2e-05" iyy="0.025057" iyz="-0.004085" izz="0.005269"/>
    </inertial>
    <visual>
      <origin rpy="0 0 0" xyz="-0.252487 0.092444 -0.003592"/>
      <geometry>
        <mesh filename="stl/rf_leg_1.stl" scale="0.001 0.001 0.001"/>
      </geometry>
      <material name="black"/>
    </visual>
    <collision>
      <origin rpy="0 0 0" xyz="-0.252487 0.092444 -0.003592"/>
      <geometry>
        <mesh filename="stl/rf_leg_1.stl" scale="0.001 0.001 0.001"/>
      </geometry>
    </collision>
    </link>
    <joint name="thigh_fr_to_knee_fr_j" type="continuous">
        <axis xyz="0.0 -1.0 0.0"/>
        <origin rpy="0 0 0" xyz="-1.1e-05 -0.101005 -0.279173"/>
        <parent link="thigh_fr"/>
        <child link="shank_fr"/>
    </joint>
    <link name="shank_fr">
    <inertial>
      <origin rpy="0 0 0" xyz="0.012966453142349954 0.011189960499004004 -0.1175400869676112"/>
      <mass value="0.11741117146712181"/>
      <inertia ixx="0.000953" ixy="0.0" ixz="0.000137" iyy="0.000982" iyz="-0.0" izz="3.8e-05"/>
    </inertial>
    <visual>
      <origin rpy="0 0 0" xyz="-0.252476 0.193449 0.275581"/>
      <geometry>
        <mesh filename="stl/rf_lowleg_1.stl" scale="0.001 0.001 0.001"/>
      </geometry>
      <material name="black"/>
    </visual>
    <collision>
      <origin rpy="0 0 0" xyz="-0.252476 0.193449 0.275581"/>
      <geometry>
        <mesh filename="stl/rf_lowleg_1.stl" scale="0.001 0.001 0.001"/>
      </geometry>
    </collision>
    </link>
    <link name="toe_fr">
    <contact>
      <friction_anchor/>
      <stiffness value="30000.0"/>
      <damping value="1000.0"/>
      <spinning_friction value="0.3"/>
      <lateral_friction value="3.0"/>
    </contact>
    <visual>
      <origin rpy="0 0 0" xyz="-0.288204 0.175249 0.559142"/>
      <geometry>
        <mesh filename="stl/rf_foot_1.stl" scale="0.001 0.001 0.001"/>
      </geometry>
      <material name="white"/>
    </visual>
    <collision>
      <origin rpy="0 0 0" xyz="-0.288204 0.175249 0.559142"/>
      <geometry>
        <mesh filename="stl/rf_foot_1.stl" scale="0.001 0.001 0.001"/>
      </geometry>
    </collision>
    <inertial>
      <origin rpy="0 0 0" xyz="-0.0004841082735168589 -0.006999865033764652 0.006815977676136731"/>
      <mass value="0.15329743789754363"/>
      <inertia ixx="3.2e-05" ixy="0.0" ixz="1e-06" iyy="4.2e-05" iyz="-0.0" izz="1.7e-05"/>
    </inertial>
  </link>
  <joint name="toe_fr_joint" type="fixed">
    <parent link="shank_fr"/>
    <child link="toe_fr"/>
    <origin rpy="0 0 0" xyz="0.035728 0.0182 -0.283561"/>
    <dynamics damping="0.0" friction="0.0"/>

  </joint>
<!--!!!!!!!!!!!! Front Left Leg !!!!!!!!!!!!!!!!!!!!!!!!!!!!!!!!!!!!-->
    <joint name="torso_to_abduct_fl_j" type="continuous">
        <axis xyz="1.0 0.0 0.0"/>
        <origin rpy="0 0 0" xyz="0.194567 0.048706 0.003592"/>
        <parent link="body"/>
        <child link="abduct_fl"/>
    </joint>
    <link name="abduct_fl">
    <inertial>
      <origin rpy="0 0 0" xyz="0.05316643515331182 0.000550720182022707 0.0005858398004480255"/>
      <mass value="1.114"/>
      <inertia ixx="0.002477" ixy="-1.3e-05" ixz="3.2e-05" iyy="0.003947" iyz="1.1e-05" izz="0.002928"/>
    </inertial>
    <visual>
      <origin rpy="0 0 0" xyz="-0.194567 -0.048706 -0.003592"/>
      <geometry>
        <mesh filename="stl/lh_hip_1.stl" scale="0.001 0.001 0.001"/>
      </geometry>
      <material name="black"/>
    </visual>
    <collision>
      <origin rpy="0 0 0" xyz="-0.194567 -0.048706 -0.003592"/>
      <geometry>
        <mesh filename="stl/lh_hip_1.stl" scale="0.001 0.001 0.001"/>
      </geometry>
    </collision>
    </link>
    <joint name="abduct_fl_to_thigh_fl_j" type="continuous">
        <axis xyz="0.0 -1.0 0.0"/>
        <origin rpy="0 0 0" xyz="0.05792 0.03115 0.0"/>
        <parent link="abduct_fl"/>
        <child link="thigh_fl"/>
    </joint>
    <link name="thigh_fl">
    <inertial>
      <origin rpy="0 0 0" xyz="0.00047044463767242917 0.05813747232667811 -0.0292515806223483"/>
      <mass value="1.575"/>
      <inertia ixx="0.025689" ixy="7.8e-05" ixz="-3.2e-05" iyy="0.025057" iyz="0.004085" izz="0.005269"/>
    </inertial>
    <visual>
      <origin rpy="0 0 0" xyz="-0.252487 -0.079856 -0.003592"/>
      <geometry>
        <mesh filename="stl/lf_leg_1.stl" scale="0.001 0.001 0.001"/>
      </geometry>
      <material name="black"/>
    </visual>
    <collision>
      <origin rpy="0 0 0" xyz="-0.252487 -0.079856 -0.003592"/>
      <geometry>
        <mesh filename="stl/lf_leg_1.stl" scale="0.001 0.001 0.001"/>
      </geometry>
    </collision>
    </link>

    <joint name="thigh_fl_to_knee_fl_j" type="continuous">
        <axis xyz="0.0 -1.0 0.0"/>
        <origin rpy="0 0 0" xyz="1.1e-05 0.101005 -0.279173"/>
        <parent link="thigh_fl"/>
        <child link="shank_fl"/>
    </joint>
    <link name="shank_fl">
    <inertial>
      <origin rpy="0 0 0" xyz="0.012966291166638166 -0.011210239998497795 -0.11754008696762525"/>
      <mass value="0.11741117146712181"/>
      <inertia ixx="0.000953" ixy="0.0" ixz="0.000137" iyy="0.000982" iyz="-0.0" izz="3.8e-05"/>
    </inertial>
    <visual>
      <origin rpy="0 0 0" xyz="-0.252498 -0.180861 0.275581"/>
      <geometry>
        <mesh filename="stl/lf_lowleg_1.stl" scale="0.001 0.001 0.001"/>
      </geometry>
      <material name="black"/>
    </visual>
    <collision>
      <origin rpy="0 0 0" xyz="-0.252498 -0.180861 0.275581"/>
      <geometry>
        <mesh filename="stl/lf_lowleg_1.stl" scale="0.001 0.001 0.001"/>
      </geometry>
    </collision>
    </link>
    <link name="toe_fl">
      <contact>
      <friction_anchor/>
      <stiffness value="30000.0"/>
      <damping value="1000.0"/>
      <spinning_friction value="0.3"/>
      <lateral_friction value="3.0"/>
    </contact>
    <inertial>
      <origin rpy="0 0 0" xyz="-0.00048427024923497486 -0.007000065531260535 0.006815977676121854"/>
      <mass value="0.15329743789754363"/>
      <inertia ixx="3.2e-05" ixy="0.0" ixz="1e-06" iyy="4.2e-05" iyz="-0.0" izz="1.7e-05"/>
    </inertial>
    <visual>
      <origin rpy="0 0 0" xyz="-0.288226 -0.176661 0.559142"/>
      <geometry>
        <mesh filename="stl/lf_foot_1.stl" scale="0.001 0.001 0.001"/>
      </geometry>
      <material name="white"/>
    </visual>
    <collision>
      <origin rpy="0 0 0" xyz="-0.288226 -0.176661 0.559142"/>
      <geometry>
        <mesh filename="stl/lf_foot_1.stl" scale="0.001 0.001 0.001"/>
      </geometry>
    </collision>
  </link>
  <joint name="toe_fl_joint" type="fixed">
    <parent link="shank_fl"/>
    <child link="toe_fl"/>
    <origin rpy="0 0 0" xyz="0.035728 -0.0042 -0.283561"/>
    <dynamics damping="0.0" friction="0.0"/>
  </joint>


<!--!!!!!!!!!!!! Hind Right Leg !!!!!!!!!!!!!!!!!!!!!!!!!!!!!!!!!!!!-->
    <joint name="torso_to_abduct_hr_j" type="continuous">
        <axis xyz="1.0 0.0 0.0"/>
        <origin rpy="0 0 0" xyz="-0.180033 -0.061294 0.003592"/>
        <parent link="body"/>
        <child link="abduct_hr"/>
    </joint>
    <link name="abduct_hr">
    <inertial>
      <origin rpy="0 0 0" xyz="-0.05316679644019451 -0.000550633439046426 0.0005858398004401559"/>
      <mass value="1.114"/>
      <inertia ixx="0.002477" ixy="-1.3e-05" ixz="-3.2e-05" iyy="0.003947" iyz="-1.1e-05" izz="0.002928"/>
    </inertial>
    <visual>
      <origin rpy="0 0 0" xyz="0.180033 0.061294 -0.003592"/>
      <geometry>
        <mesh filename="stl/lh_hip_1.stl" scale="0.001 0.001 0.001"/>
      </geometry>
      <material name="black"/>
    </visual>
    <collision>
      <origin rpy="0 0 0" xyz="0.180033 0.061294 -0.003592"/>
      <geometry>
        <mesh filename="stl/lh_hip_1.stl" scale="0.001 0.001 0.001"/>
      </geometry>
    </collision>
  </link>


    <joint name="abduct_hr_to_thigh_hr_j" type="continuous">
        <axis xyz="-0.0 -1.0 0.0"/>
        <origin rpy="0 0 0" xyz="-0.05792 -0.03115 0.0"/>
        <parent link="abduct_hr"/>
        <child link="thigh_hr"/>
    </joint>
    <link name="thigh_hr">
    <inertial>
      <origin rpy="0 0 0" xyz="-0.00047080594419732225 -0.05813738558379686 -0.029251580623975794"/>
      <mass value="1.575"/>
      <inertia ixx="0.025689" ixy="7.8e-05" ixz="3.2e-05" iyy="0.025057" iyz="-0.004085" izz="0.005269"/>
    </inertial>
    <visual>
      <origin rpy="0 0 0" xyz="0.237953 0.092444 -0.003592"/>
      <geometry>
        <mesh filename="stl/rh_leg_1.stl" scale="0.001 0.001 0.001"/>
      </geometry>
      <material name="black"/>
    </visual>
    <collision>
      <origin rpy="0 0 0" xyz="0.237953 0.092444 -0.003592"/>
      <geometry>
        <mesh filename="stl/rh_leg_1.stl" scale="0.001 0.001 0.001"/>
      </geometry>
    </collision>
    </link>

    <joint name="thigh_hr_to_knee_hr_j" type="continuous">
        <axis xyz="0.0 -1.0 0.0"/>
        <origin rpy="0 0 0" xyz="-1.1e-05 -0.101005 -0.279173"/>
        <parent link="thigh_hr"/>
        <child link="shank_hr"/>
    </joint>
    <link name="shank_hr">
    <inertial>
      <origin rpy="0 0 0" xyz="0.012966607024813698 0.011189960499010054 -0.11754008696762136"/>
      <mass value="0.11741117146712181"/>
      <inertia ixx="0.000953" ixy="0.0" ixz="0.000137" iyy="0.000982" iyz="-0.0" izz="3.8e-05"/>
    </inertial>
    <visual>
      <origin rpy="0 0 0" xyz="0.237964 0.193449 0.275581"/>
      <geometry>
        <mesh filename="stl/rh_lowleg_1.stl" scale="0.001 0.001 0.001"/>
      </geometry>
      <material name="black"/>
    </visual>
    <collision>
      <origin rpy="0 0 0" xyz="0.237964 0.193449 0.275581"/>
      <geometry>
        <mesh filename="stl/rh_lowleg_1.stl" scale="0.001 0.001 0.001"/>
      </geometry>
    </collision>
    </link>
     <link name="toe_hr">
      <contact>
      <friction_anchor/>
      <stiffness value="30000.0"/>
      <damping value="1000.0"/>
      <spinning_friction value="0.3"/>
      <lateral_friction value="3.0"/>
    </contact>
    <inertial>
      <origin rpy="0 0 0" xyz="-0.0004849543910595 -0.006999865033758906 0.0068159776761256285"/>
      <mass value="0.15329743789754363"/>
      <inertia ixx="3.2e-05" ixy="0.0" ixz="1e-06" iyy="4.2e-05" iyz="-0.0" izz="1.7e-05"/>
    </inertial>
    <visual>
      <origin rpy="0 0 0" xyz="0.202235 0.175249 0.559142"/>
      <geometry>
        <mesh filename="stl/rh_foot_1.stl" scale="0.001 0.001 0.001"/>
      </geometry>
      <material name="white"/>
    </visual>
    <collision>
      <origin rpy="0 0 0" xyz="0.202235 0.175249 0.559142"/>
      <geometry>
        <mesh filename="stl/rh_foot_1.stl" scale="0.001 0.001 0.001"/>
      </geometry>
    </collision>
  </link>
  <joint name="toe_hr_joint" type="fixed">
    <parent link="shank_hr"/>
    <child link="toe_hr"/>
    <origin rpy="0 0 0" xyz="0.035729 0.0182 -0.283561"/>
    <dynamics damping="0.0" friction="0.0"/>
  </joint>


<!--!!!!!!!!!!!! Hind Left Leg !!!!!!!!!!!!!!!!!!!!!!!!!!!!!!!!!!!!-->
    <joint name="torso_to_abduct_hl_j" type="continuous">
        <axis xyz="1.0 0.0 0.0"/>
        <origin rpy="0 0 0" xyz="-0.180033 0.048706 0.003592"/>
        <parent link="body"/>
        <child link="abduct_hl"/>
    </joint>
    <link name="abduct_hl">
    <inertial>
      <origin rpy="0 0 0" xyz="-0.05316679644019415 0.0005507201820246221 0.0005858398004397222"/>
      <mass value="1.114"/>
      <inertia ixx="0.002477" ixy="1.3e-05" ixz="-3.2e-05" iyy="0.003947" iyz="1.1e-05" izz="0.002928"/>
    </inertial>
    <visual>
      <origin rpy="0 0 0" xyz="0.180033 -0.048706 -0.003592"/>
      <geometry>
        <mesh filename="stl/lh_hip_1.stl" scale="0.001 0.001 0.001"/>
      </geometry>
      <material name="black"/>
    </visual>
    <collision>
      <origin rpy="0 0 0" xyz="0.180033 -0.048706 -0.003592"/>
      <geometry>
        <mesh filename="stl/lh_hip_1.stl" scale="0.001 0.001 0.001"/>
      </geometry>
    </collision>
    </link>

    <joint name="abduct_hl_to_thigh_hl_j" type="continuous">
        <axis xyz="0.0 -1.0 0.0"/>
        <origin rpy="0 0 0" xyz="-0.05792 0.03115 0.0"/>
        <parent link="abduct_hl"/>
        <child link="thigh_hl"/>
    </joint>
    <link name="thigh_hl">
    <inertial>
      <origin rpy="0 0 0" xyz="0.0004705985201587659 0.058137472326679665 -0.029251580622356724"/>
      <mass value="1.575"/>
      <inertia ixx="0.025689" ixy="7.8e-05" ixz="-3.2e-05" iyy="0.025057" iyz="0.004085" izz="0.005269"/>
    </inertial>
    <visual>
      <origin rpy="0 0 0" xyz="0.237953 -0.079856 -0.003592"/>
      <geometry>
        <mesh filename="stl/lh_leg_1.stl" scale="0.001 0.001 0.001"/>
      </geometry>
      <material name="black"/>
    </visual>
    <collision>
      <origin rpy="0 0 0" xyz="0.237953 -0.079856 -0.003592"/>
      <geometry>
        <mesh filename="stl/lh_leg_1.stl" scale="0.001 0.001 0.001"/>
      </geometry>
    </collision>
    </link>

    <joint name="thigh_hl_to_knee_hl_j" type="continuous">
        <axis xyz="0.0 -1.0 0.0"/>
        <origin rpy="0 0 0" xyz="1.1e-05 0.101005 -0.279173"/>
        <parent link="thigh_hl"/>
        <child link="shank_hl"/>
    </joint>
    <link name="shank_hl">
    <inertial>
      <origin rpy="0 0 0" xyz="0.012966445049139047 -0.011210239998496796 -0.11754008696763224"/>
      <mass value="0.11741117146712189"/>
      <inertia ixx="0.000953" ixy="0.0" ixz="0.000137" iyy="0.000982" iyz="-0.0" izz="3.8e-05"/>
    </inertial>
    <visual>
      <origin rpy="0 0 0" xyz="0.237942 -0.180861 0.275581"/>
      <geometry>
        <mesh filename="stl/lh_lowleg_1.stl" scale="0.001 0.001 0.001"/>
      </geometry>
      <material name="black"/>
    </visual>
    <collision>
      <origin rpy="0 0 0" xyz="0.237942 -0.180861 0.275581"/>
      <geometry>
        <mesh filename="stl/lh_lowleg_1.stl" scale="0.001 0.001 0.001"/>
      </geometry>
    </collision>
    </link>
    <link name="toe_hl">
      <contact>
      <friction_anchor/>
      <stiffness value="30000.0"/>
      <damping value="1000.0"/>
      <spinning_friction value="0.3"/>
      <lateral_friction value="3.0"/>
    </contact>
    <inertial>
      <origin rpy="0 0 0" xyz="-0.0004841163667276549 -0.007000065531259675 0.0068159776761156365"/>
      <mass value="0.15329743789754363"/>
      <inertia ixx="3.2e-05" ixy="0.0" ixz="1e-06" iyy="4.2e-05" iyz="-0.0" izz="1.7e-05"/>
    </inertial>
    <visual>
      <origin rpy="0 0 0" xyz="0.202214 -0.176661 0.559142"/>
      <geometry>
        <mesh filename="stl/lh_foot_1.stl" scale="0.001 0.001 0.001"/>
      </geometry>
      <material name="white"/>
    </visual>
    <collision>
      <origin rpy="0 0 0" xyz="0.202214 -0.176661 0.559142"/>
      <geometry>
        <mesh filename="stl/lh_foot_1.stl" scale="0.001 0.001 0.001"/>
      </geometry>
    </collision>
  </link>
  <joint name="toe_hl_joint" type="fixed">
    <parent link="shank_hl"/>
    <child link="toe_hl"/>
    <origin rpy="0 0 0" xyz="0.035728 -0.0042 -0.283561"/>
    <dynamics damping="0.0" friction="0.0"/>
  </joint>
</robot>
